Workbook
Name Slicer_CustomerType1: #N/A
Name Slicer_CustomerType2: #N/A
Name Slicer_PaymentMethod: #N/A
Name Slicer_Product: #N/A
Name Slicer_Region: #N/A
Name Slicer_RegionManager: #N/A
Name Slicer_Years__OrderDate: #N/A

Sheet Sheet2
A3: Row Labels | B3: Sum of Net Sales | C3: Sum of Profit | E3: Sales vc PY | F3: Sales vc PY
A4: 2023 | B4: 1697870 | C4: -132848.99
A5: 2024 | B5: 1771954.8 | C5: -140330.63 | E5: =B5/B4-1 -> 0.043633968 | F5: =C5/C4-1 -> 0.056316847
A6: 2025 | B6: 910167.67 | C6: -74720.888
A7: Grand Total | B7: 4379992.4 | C7: -347900.51
A9: Sale

Sheet Sheet3
A1: Table 1&2
A3: Sum of Net Sales | B3: Column Labels | G3: Sum of Net Sales | H3: Column Labels
B4: 2023 | C4: 2024 | H4: 2023 | I4: 2024
A7: Row Labels | G7: Row Labels
A8: Tablet | B8: 268581.74 | C8: 297185.16 | G8: Central | H8: 317187.37 | I8: 316403.47
A9: Monitor | B9: 252496.86 | C9: 294518.33 | G9: East | H9: 311347.12 | I9: 361402.37
A10: Laptop | B10: 286177.2 | C10: 256697.07 | G10: North | H10: 360780.62 | I10: 377736.99
A11: Printer | B11: 222621.63 | C11: 319790.82 | G11: South | H11: 330323.74 | I11: 382472.17
A12: Chair | B12: 205814.54 | C12: 248450.11 | G12: West | H12: 378231.13 | I12: 333939.79
A13: Desk | B13: 257695.83 | C13: 185283.95 | G13: Grand Total | H13: 1697870 | I13: 1771954.8
A14: Phone | B14: 204482.17 | C14: 170029.35
A15: Grand Total | B15: 1697870 | C15: 1771954.8
A18: Table 3& 4
A20: Sum of Net Sales | B20: Column Labels | G20: Sum of Net Sales | H20: Column Labels
B21: 2023 | C21: 2024 | H21: 2023 | I21: 2024
A24: Row Labels | G24: Row Labels
A25: Tablet | B25: 268581.74 | C25: 297185.16 | G25: Central | H25: 317187.37 | I25: 316403.47
A26: Monitor | B26: 252496.86 | C26: 294518.33 | G26: East | H26: 311347.12 | I26: 361402.37
A27: Laptop | B27: 286177.2 | C27: 256697.07 | G27: North | H27: 360780.62 | I27: 377736.99
A28: Printer | B28: 222621.63 | C28: 319790.82 | G28: South | H28: 330323.74 | I28: 382472.17
A29: Chair | B29: 205814.54 | C29: 248450.11 | G29: West | H29: 378231.13 | I29: 333939.79
A30: Desk | B30: 257695.83 | C30: 185283.95 | G30: Grand Total | H30: 1697870 | I30: 1771954.8
A31: Phone | B31: 204482.17 | C31: 170029.35
A32: Grand Total | B32: 1697870 | C32: 1771954.8

Sheet Sheet4
A3: Years (OrderDate) | B3: Quarters (OrderDate) | C3: Sum of Net Sales | D3: Sum of Quantity | H3: Sales | I3: Price
A4: 2023 | B4: Qtr1 | C4: 502717.8 | D4: 1753 | F4: =A4 -> 2023 | G4: =B4 -> Qtr1 | H4: =C4 -> 502717.8 | I4: =H4/D4 -> 286.7757
B5: Qtr2 | C5: 400622.36 | D5: 1343 | G5: =B5 -> Qtr2 | H5: =C5 -> 400622.36 | I5: =H5/D5 -> 298.30407
B6: Qtr3 | C6: 451217.88 | D6: 1608 | G6: =B6 -> Qtr3 | H6: =C6 -> 451217.88 | I6: =H6/D6 -> 280.60814
B7: Qtr4 | C7: 343311.94 | D7: 1350 | G7: =B7 -> Qtr4 | H7: =C7 -> 343311.94 | I7: =H7/D7 -> 254.30514
A8: 2024 | B8: Qtr1 | C8: 450312.98 | D8: 1618 | F8: =A8 -> 2024 | G8: =B8 -> Qtr1 | H8: =C8 -> 450312.98 | I8: =H8/D8 -> 278.31457
B9: Qtr2 | C9: 461674.88 | D9: 1549 | G9: =B9 -> Qtr2 | H9: =C9 -> 461674.88 | I9: =H9/D9 -> 298.04705
B10: Qtr3 | C10: 400585.82 | D10: 1460 | G10: =B10 -> Qtr3 | H10: =C10 -> 400585.82 | I10: =H10/D10 -> 274.37385
B11: Qtr4 | C11: 459381.1 | D11: 1588 | G11: =B11 -> Qtr4 | H11: =C11 -> 459381.1 | I11: =H11/D11 -> 289.28281
A12: 2025 | B12: Qtr1 | C12: 492476.49 | D12: 1844 | F12: =A12 -> 2025 | G12: =B12 -> Qtr1 | H12: =C12 -> 492476.49 | I12: =H12/D12 -> 267.06968
B13: Qtr2 | C13: 417691.18 | D13: 1503 | G13: =B13 -> Qtr2 | H13: =C13 -> 417691.18 | I13: =H13/D13 -> 277.90497
A14: Grand Total | C14: 4379992.4 | D14: 15616
A39: Region | B39: Sum of Net Sales | C39: Sum of Quantity | E39: Region | F39: Sales
A40: North | B40: 967957.98 | C40: 3442 | E40: =A40 -> North | F40: =B40 -> 967957.98
A41: East | B41: 883633.72 | C41: 3078 | E41: =A41 -> East | F41: =B41 -> 883633.72
A42: West | B42: 853478.86 | C42: 3041 | E42: =A42 -> West | F42: =B42 -> 853478.86
A43: Central | B43: 847153.68 | C43: 3102 | E43: =A43 -> Central | F43: =B43 -> 847153.68
A44: South | B44: 827768.19 | C44: 2953 | E44: =A44 -> South | F44: =B44 -> 827768.19
A45: Grand Total | B45: 4379992.4 | C45: 15616

Sheet Sheet5
B16: Product | D16: 2023 | E16: 2024 | F16: vs PY | H16: Region | J16: 2023 | K16: 2024 | L16: vs PY | N16: Product | P16: 2023 | Q16: 2024 | R16: vs PY | T16: Region | V16: 2023 | W16: 2024 | X16: vs PY
B17: =Sheet3!A8 -> Tablet | D17: =Sheet3!B8 -> 268581.74 | E17: =Sheet3!C8 -> 297185.16 | F17: =D17/E17-1 -> -0.096247817 | H17: =Sheet3!G8 -> Central | J17: =Sheet3!H8 -> 317187.37 | K17: =Sheet3!I8 -> 316403.47 | L17: =J17/K17-1 -> 0.0024775456 | N17: =Sheet3!A25 -> Tablet | P17: =Sheet3!B25 -> 268581.74 | Q17: =Sheet3!C25 -> 297185.16 | R17: =P17/Q17-1 -> -0.096247817 | T17: =Sheet3!G25 -> Central | V17: =Sheet3!H25 -> 317187.37 | W17: =Sheet3!I25 -> 316403.47 | X17: =V17/W17-1 -> 0.0024775456
B18: =Sheet3!A9 -> Monitor | D18: =Sheet3!B9 -> 252496.86 | E18: =Sheet3!C9 -> 294518.33 | F18: =D18/E18-1 -> -0.1426786 | H18: =Sheet3!G9 -> East | J18: =Sheet3!H9 -> 311347.12 | K18: =Sheet3!I9 -> 361402.37 | L18: =J18/K18-1 -> -0.13850283 | N18: =Sheet3!A26 -> Monitor | P18: =Sheet3!B26 -> 252496.86 | Q18: =Sheet3!C26 -> 294518.33 | R18: =P18/Q18-1 -> -0.1426786 | T18: =Sheet3!G26 -> East | V18: =Sheet3!H26 -> 311347.12 | W18: =Sheet3!I26 -> 361402.37 | X18: =V18/W18-1 -> -0.13850283
B19: =Sheet3!A10 -> Laptop | D19: =Sheet3!B10 -> 286177.2 | E19: =Sheet3!C10 -> 256697.07 | F19: =D19/E19-1 -> 0.11484406 | H19: =Sheet3!G10 -> North | J19: =Sheet3!H10 -> 360780.62 | K19: =Sheet3!I10 -> 377736.99 | L19: =J19/K19-1 -> -0.044889345 | N19: =Sheet3!A27 -> Laptop | P19: =Sheet3!B27 -> 286177.2 | Q19: =Sheet3!C27 -> 256697.07 | R19: =P19/Q19-1 -> 0.11484406 | T19: =Sheet3!G27 -> North | V19: =Sheet3!H27 -> 360780.62 | W19: =Sheet3!I27 -> 377736.99 | X19: =V19/W19-1 -> -0.044889345
B20: =Sheet3!A11 -> Printer | D20: =Sheet3!B11 -> 222621.63 | E20: =Sheet3!C11 -> 319790.82 | F20: =D20/E20-1 -> -0.30385235 | H20: =Sheet3!G11 -> South | J20: =Sheet3!H11 -> 330323.74 | K20: =Sheet3!I11 -> 382472.17 | L20: =J20/K20-1 -> -0.13634568 | N20: =Sheet3!A28 -> Printer | P20: =Sheet3!B28 -> 222621.63 | Q20: =Sheet3!C28 -> 319790.82 | R20: =P20/Q20-1 -> -0.30385235 | T20: =Sheet3!G28 -> South | V20: =Sheet3!H28 -> 330323.74 | W20: =Sheet3!I28 -> 382472.17 | X20: =V20/W20-1 -> -0.13634568
B21: =Sheet3!A12 -> Chair | D21: =Sheet3!B12 -> 205814.54 | E21: =Sheet3!C12 -> 248450.11 | F21: =D21/E21-1 -> -0.17160613 | H21: =Sheet3!G12 -> West | J21: =Sheet3!H12 -> 378231.13 | K21: =Sheet3!I12 -> 333939.79 | L21: =J21/K21-1 -> 0.13263271 | N21: =Sheet3!A29 -> Chair | P21: =Sheet3!B29 -> 205814.54 | Q21: =Sheet3!C29 -> 248450.11 | R21: =P21/Q21-1 -> -0.17160613 | T21: =Sheet3!G29 -> West | V21: =Sheet3!H29 -> 378231.13 | W21: =Sheet3!I29 -> 333939.79 | X21: =V21/W21-1 -> 0.13263271
B22: =Sheet3!A13 -> Desk | D22: =Sheet3!B13 -> 257695.83 | E22: =Sheet3!C13 -> 185283.95 | F22: =D22/E22-1 -> 0.39081574 | H22: Total | J22: =Sheet3!H13 -> 1697870 | K22: =Sheet3!I13 -> 1771954.8 | L22: =J22/K22-1 -> -0.041809647 | N22: =Sheet3!A30 -> Desk | P22: =Sheet3!B30 -> 257695.83 | Q22: =Sheet3!C30 -> 185283.95 | R22: =P22/Q22-1 -> 0.39081574 | T22: Total | V22: =Sheet3!H30 -> 1697870 | W22: =Sheet3!I30 -> 1771954.8 | X22: =V22/W22-1 -> -0.041809647
B23: =Sheet3!A14 -> Phone | D23: =Sheet3!B14 -> 204482.17 | E23: =Sheet3!C14 -> 170029.35 | F23: =D23/E23-1 -> 0.20262869 | N23: =Sheet3!A31 -> Phone | P23: =Sheet3!B31 -> 204482.17 | Q23: =Sheet3!C31 -> 170029.35 | R23: =P23/Q23-1 -> 0.20262869
B24: Total | D24: =Sheet3!B15 -> 1697870 | E24: =Sheet3!C15 -> 1771954.8 | F24: =D24/E24-1 -> -0.041809647 | N24: Total | P24: =Sheet3!B32 -> 1697870 | Q24: =Sheet3!C32 -> 1771954.8 | R24: =P24/Q24-1 -> -0.041809647

Sheet Sheet1
A1: Date | B1: Region | C1: Product | D1: Quantity | E1: UnitPrice | F1: StoreLocation | G1: CustomerType | H1: Discount | I1: Salesperson | J1: TotalPrice | K1: PaymentMethod | L1: Promotion | M1: Returned | N1: OrderID | O1: CustomerName | P1: ShippingCost | Q1: OrderDate | R1: DeliveryDate | S1: RegionManager | T1: Gross Revenue | U1: Discount AmountA | V1: Net Sales | W1: Delivery Time | X1: Profit | Y1: Is Returned
A2: 44980 | B2: East | C2: Laptop | D2: 14 | E2: 163.6 | F2: Store B | G2: Wholesale | H2: 0 | I2: Eva | J2: 2290.4 | K2: Online | L2: FREESHIP | M2: 0 | N2: REG100000 | O2: Cust 6583 | P2: 43.34 | Q2: 44980 | R2: 44984 | S2: Eric | T2: =D2*E2 -> 2290.4 | U2: =T2*H2 -> 0 | V2: =T2-U2 -> 2290.4 | W2: =R2-Q2 -> 4 | X2: =V2-(E2*D2) -> 0 | Y2: =IF(M2 = "Yes", -V2,0) -> 0
A3: 45645 | B3: South | C3: Phone | D3: 1 | E3: 544.01 | F3: Store A | G3: Retail | H3: 0 | I3: Alice | J3: 544.01 | K3: Gift Card | L3: SAVE10 | M3: 0 | N3: REG100001 | O3: Cust 2144 | P3: 5.3 | Q3: 45645 | R3: 45654 | S3: Sophie | T3: =D3*E3 -> 544.01 | U3: =T3*H3 -> 0 | V3: =T3-U3 -> 544.01 | W3: =R3-Q3 -> 9 | X3: =V3-(E3*D3) -> 0 | Y3: =IF(M3 = "Yes", -V3,0) -> 0
A4: 45056 | B4: North | C4: Desk | D4: 14 | E4: 346.18 | F4: Store B | G4: Wholesale | H4: 0.1 | I4: Alice | J4: 4361.868 | K4: Online | L4: WINTER15 | M4: 0 | N4: REG100002 | O4: Cust 5998 | P4: 20.46 | Q4: 45056 | R4: 45065 | S4: Ryan | T4: =D4*E4 -> 4846.52 | U4: =T4*H4 -> 484.652 | V4: =T4-U4 -> 4361.868 | W4: =R4-Q4 -> 9 | X4: =V4-(E4*D4) -> -484.652 | Y4: =IF(M4 = "Yes", -V4,0) -> 0
A5: 45714 | B5: Central | C5: Chair | D5: 18 | E5: 384.82 | F5: Store A | G5: Wholesale | H5: 0.15 | I5: Frank | J5: 5887.746 | K5: Gift Card | L5: FREESHIP | M5: 0 | N5: REG100003 | O5: Cust 7136 | P5: 27.95 | Q5: 45714 | R5: 45718 | S5: Cameron | T5: =D5*E5 -> 6926.76 | U5: =T5*H5 -> 1039.014 | V5: =T5-U5 -> 5887.746 | W5: =R5-Q5 -> 4 | X5: =V5-(E5*D5) -> -1039.014 | Y5: =IF(M5 = "Yes", -V5,0) -> 0
A6: 45101 | B6: East | C6: Desk | D6: 18 | E6: 237.76 | F6: Store C | G6: Retail | H6: 0 | I6: Carlos | J6: 4279.68 | K6: Online | L6: SAVE10 | M6: 0 | N6: REG100004 | O6: Cust 6506 | P6: 5.73 | Q6: 45101 | R6: 45104 | S6: Eric | T6: =D6*E6 -> 4279.68 | U6: =T6*H6 -> 0 | V6: =T6-U6 -> 4279.68 | W6: =R6-Q6 -> 3 | X6: =V6-(E6*D6) -> 0 | Y6: =IF(M6 = "Yes", -V6,0) -> 0
A7: 45342 | B7: Central | C7: Monitor | D7: 2 | E7: 385.09 | F7: Store D | G7: Wholesale | H7: 0.15 | I7: Diana | J7: 654.653 | K7: Credit Card | M7: 0 | N7: REG100005 | O7: Cust 3909 | P7: 11.92 | Q7: 45342 | R7: 45352 | S7: Cameron | T7: =D7*E7 -> 770.18 | U7: =T7*H7 -> 115.527 | V7: =T7-U7 -> 654.653 | W7: =R7-Q7 -> 10 | X7: =V7-(E7*D7) -> -115.527 | Y7: =IF(M7 = "Yes", -V7,0) -> 0
A8: 44937 | B8: South | C8: Chair | D8: 7 | E8: 17.5 | F8: Store C | G8: Retail | H8: 0.1 | I8: Alice | J8: 110.25 | K8: Debit Card | L8: WINTER15 | M8: 0 | N8: REG100006 | O8: Cust 7887 | P8: 5.02 | Q8: 44937 | R8: 44940 | S8: Sophie | T8: =D8*E8 -> 122.5 | U8: =T8*H8 -> 12.25 | V8: =T8-U8 -> 110.25 | W8: =R8-Q8 -> 3 | X8: =V8-(E8*D8) -> -12.25 | Y8: =IF(M8 = "Yes", -V8,0) -> 0
A9: 44935 | B9: Central | C9: Chair | D9: 3 | E9: 330.22 | F9: Store C | G9: Wholesale | H9: 0.15 | I9: Carlos | J9: 842.061 | K9: Cash | M9: 0 | N9: REG100007 | O9: Cust 5301 | P9: 48.01 | Q9: 44935 | R9: 44937 | S9: Cameron | T9: =D9*E9 -> 990.66 | U9: =T9*H9 -> 148.599 | V9: =T9-U9 -> 842.061 | W9: =R9-Q9 -> 2 | X9: =V9-(E9*D9) -> -148.599 | Y9: =IF(M9 = "Yes", -V9,0) -> 0
A10: 45581 | B10: South | C10: Chair | D10: 3 | E10: 432.04 | F10: Store D | G10: Wholesale | H10: 0.05 | I10: Bob | J10: 1231.314 | K10: Debit Card | L10: FREESHIP | M10: 1 | N10: REG100008 | O10: Cust 2284 | P10: 42.11 | Q10: 45581 | R10: 45583 | S10: Sophie | T10: =D10*E10 -> 1296.12 | U10: =T10*H10 -> 64.806 | V10: =T10-U10 -> 1231.314 | W10: =R10-Q10 -> 2 | X10: =V10-(E10*D10) -> -64.806 | Y10: =IF(M10 = "Yes", -V10,0) -> 0
A11: 45721 | B11: West | C11: Desk | D11: 5 | E11: 323.28 | F11: Store D | G11: Retail | H11: 0.1 | I11: Frank | J11: 1454.76 | K11: Gift Card | L11: SAVE10 | M11: 0 | N11: REG100009 | O11: Cust 3732 | P11: 41.1 | Q11: 45721 | R11: 45729 | S11: Wendy | T11: =D11*E11 -> 1616.4 | U11: =T11*H11 -> 161.64 | V11: =T11-U11 -> 1454.76 | W11: =R11-Q11 -> 8 | X11: =V11-(E11*D11) -> -161.64 | Y11: =IF(M11 = "Yes", -V11,0) -> 0
A12: 45392 | B12: North | C12: Desk | D12: 15 | E12: 523.29 | F12: Store B | G12: Wholesale | H12: 0.15 | I12: Eva | J12: 6671.9475 | K12: Debit Card | M12: 0 | N12: REG100010 | O12: Cust 1462 | P12: 12.14 | Q12: 45392 | R12: 45399 | S12: Ryan | T12: =D12*E12 -> 7849.35 | U12: =T12*H12 -> 1177.4025 | V12: =T12-U12 -> 6671.9475 | W12: =R12-Q12 -> 7 | X12: =V12-(E12*D12) -> -1177.4025 | Y12: =IF(M12 = "Yes", -V12,0) -> 0
A13: 45485 | B13: East | C13: Phone | D13: 19 | E13: 207.35 | F13: Store D | G13: Retail | H13: 0.1 | I13: Eva | J13: 3545.685 | K13: Gift Card | M13: 1 | N13: REG100011 | O13: Cust 4330 | P13: 44.89 | Q13: 45485 | R13: 45491 | S13: Eric | T13: =D13*E13 -> 3939.65 | U13: =T13*H13 -> 393.965 | V13: =T13-U13 -> 3545.685 | W13: =R13-Q13 -> 6 | X13: =V13-(E13*D13) -> -393.965 | Y13: =IF(M13 = "Yes", -V13,0) -> 0
A14: 45128 | B14: Central | C14: Phone | D14: 1 | E14: 120.53 | F14: Store B | G14: Retail | H14: 0.05 | I14: Diana | J14: 114.5035 | K14: Cash | L14: WINTER15 | M14: 0 | N14: REG100012 | O14: Cust 2372 | P14: 20.35 | Q14: 45128 | R14: 45138 | S14: Cameron | T14: =D14*E14 -> 120.53 | U14: =T14*H14 -> 6.0265 | V14: =T14-U14 -> 114.5035 | W14: =R14-Q14 -> 10 | X14: =V14-(E14*D14) -> -6.0265 | Y14: =IF(M14 = "Yes", -V14,0) -> 0
A15: 45675 | B15: West | C15: Tablet | D15: 1 | E15: 157.83 | F15: Store A | G15: Wholesale | H15: 0.15 | I15: Carlos | J15: 134.1555 | K15: Debit Card | M15: 0 | N15: REG100013 | O15: Cust 4672 | P15: 42.82 | Q15: 45675 | R15: 45679 | S15: Wendy | T15: =D15*E15 -> 157.83 | U15: =T15*H15 -> 23.6745 | V15: =T15-U15 -> 134.1555 | W15: =R15-Q15 -> 4 | X15: =V15-(E15*D15) -> -23.6745 | Y15: =IF(M15 = "Yes", -V15,0) -> 0
A16: 45634 | B16: North | C16: Desk | D16: 15 | E16: 220.3 | F16: Store B | G16: Retail | H16: 0.15 | I16: Diana | J16: 2808.825 | K16: Debit Card | M16: 0 | N16: REG100014 | O16: Cust 4548 | P16: 39.66 | Q16: 45634 | R16: 45641 | S16: Ryan | T16: =D16*E16 -> 3304.5 | U16: =T16*H16 -> 495.675 | V16: =T16-U16 -> 2808.825 | W16: =R16-Q16 -> 7 | X16: =V16-(E16*D16) -> -495.675 | Y16: =IF(M16 = "Yes", -V16,0) -> 0
A17: 45788 | B17: West | C17: Chair | D17: 17 | E17: 162.96 | F17: Store A | G17: Wholesale | H17: 0.05 | I17: Eva | J17: 2631.804 | K17: Gift Card | L17: FREESHIP | M17: 0 | N17: REG100015 | O17: Cust 7037 | P17: 8.11 | Q17: 45788 | R17: 45794 | S17: Wendy | T17: =D17*E17 -> 2770.32 | U17: =T17*H17 -> 138.516 | V17: =T17-U17 -> 2631.804 | W17: =R17-Q17 -> 6 | X17: =V17-(E17*D17) -> -138.516 | Y17: =IF(M17 = "Yes", -V17,0) -> 0
A18: 44983 | B18: West | C18: Laptop | D18: 19 | E18: 236.11 | F18: Store D | G18: Wholesale | H18: 0 | I18: Bob | J18: 4486.09 | K18: Online | L18: WINTER15 | M18: 0 | N18: REG100016 | O18: Cust 4975 | P18: 34.11 | Q18: 44983 | R18: 44989 | S18: Wendy | T18: =D18*E18 -> 4486.09 | U18: =T18*H18 -> 0 | V18: =T18-U18 -> 4486.09 | W18: =R18-Q18 -> 6 | X18: =V18-(E18*D18) -> 0 | Y18: =IF(M18 = "Yes", -V18,0) -> 0
A19: 45440 | B19: Central | C19: Desk | D19: 11 | E19: 573.14 | F19: Store D | G19: Retail | H19: 0.05 | I19: Diana | J19: 5989.313 | K19: Cash | L19: SAVE10 | M19: 0 | N19: REG100017 | O19: Cust 8014 | P19: 34.71 | Q19: 45440 | R19: 45444 | S19: Cameron | T19: =D19*E19 -> 6304.54 | U19: =T19*H19 -> 315.227 | V19: =T19-U19 -> 5989.313 | W19: =R19-Q19 -> 4 | X19: =V19-(E19*D19) -> -315.227 | Y19: =IF(M19 = "Yes", -V19,0) -> 0
A20: 45260 | B20: East | C20: Phone | D20: 20 | E20: 519.04 | F20: Store B | G20: Retail | H20: 0.15 | I20: Carlos | J20: 8823.68 | K20: Gift Card | L20: FREESHIP | M20: 0 | N20: REG100018 | O20: Cust 1228 | P20: 19.43 | Q20: 45260 | R20: 45268 | S20: Eric | T20: =D20*E20 -> 10380.8 | U20: =T20*H20 -> 1557.12 | V20: =T20-U20 -> 8823.68 | W20: =R20-Q20 -> 8 | X20: =V20-(E20*D20) -> -1557.12 | Y20: =IF(M20 = "Yes", -V20,0) -> 0
A21: 45099 | B21: West | C21: Desk | D21: 14 | E21: 30.83 | F21: Store B | G21: Retail | H21: 0 | I21: Carlos | J21: 431.62 | K21: Online | L21: WINTER15 | M21: 1 | N21: REG100019 | O21: Cust 4247 | P21: 7.1 | Q21: 45099 | R21: 45109 | S21: Wendy | T21: =D21*E21 -> 431.62 | U21: =T21*H21 -> 0 | V21: =T21-U21 -> 431.62 | W21: =R21-Q21 -> 10 | X21: =V21-(E21*D21) -> 0 | Y21: =IF(M21 = "Yes", -V21,0) -> 0
A22: 45813 | B22: West | C22: Phone | D22: 10 | E22: 319.05 | F22: Store D | G22: Wholesale | H22: 0 | I22: Diana | J22: 3190.5 | K22: Online | M22: 0 | N22: REG100020 | O22: Cust 4199 | P22: 28.43 | Q22: 45813 | R22: 45816 | S22: Wendy | T22: =D22*E22 -> 3190.5 | U22: =T22*H22 -> 0 | V22: =T22-U22 -> 3190.5 | W22: =R22-Q22 -> 3 | X22: =V22-(E22*D22) -> 0 | Y22: =IF(M22 = "Yes", -V22,0) -> 0
A23: 44988 | B23: Central | C23: Chair | D23: 14 | E23: 312.79 | F23: Store A | G23: Retail | H23: 0.05 | I23: Bob | J23: 4160.107 | K23: Online | M23: 1 | N23: REG100021 | O23: Cust 4186 | P23: 46.83 | Q23: 44988 | R23: 44993 | S23: Cameron | T23: =D23*E23 -> 4379.06 | U23: =T23*H23 -> 218.953 | V23: =T23-U23 -> 4160.107 | W23: =R23-Q23 -> 5 | X23: =V23-(E23*D23) -> -218.953 | Y23: =IF(M23 = "Yes", -V23,0) -> 0
A24: 45340 | B24: North | C24: Laptop | D24: 14 | E24: 395.45 | F24: Store C | G24: Retail | H24: 0 | I24: Carlos | J24: 5536.3 | K24: Cash | L24: FREESHIP | M24: 1 | N24: REG100022 | O24: Cust 8137 | P24: 36.45 | Q24: 45340 | R24: 45344 | S24: Ryan | T24: =D24*E24 -> 5536.3 | U24: =T24*H24 -> 0 | V24: =T24-U24 -> 5536.3 | W24: =R24-Q24 -> 4 | X24: =V24-(E24*D24) -> 0 | Y24: =IF(M24 = "Yes", -V24,0) -> 0
A25: 45144 | B25: Central | C25: Laptop | D25: 12 | E25: 472.72 | F25: Store D | G25: Retail | H25: 0.15 | I25: Diana | J25: 4821.744 | K25: Credit Card | M25: 0 | N25: REG100023 | O25: Cust 4638 | P25: 27.97 | Q25: 45144 | R25: 45152 | S25: Cameron | T25: =D25*E25 -> 5672.64 | U25: =T25*H25 -> 850.896 | V25: =T25-U25 -> 4821.744 | W25: =R25-Q25 -> 8 | X25: =V25-(E25*D25) -> -850.896 | Y25: =IF(M25 = "Yes", -V25,0) -> 0
A26: 45435 | B26: North | C26: Desk | D26: 5 | E26: 288.01 | F26: Store A | G26: Wholesale | H26: 0 | I26: Eva | J26: 1440.05 | K26: Credit Card | L26: FREESHIP | M26: 0 | N26: REG100024 | O26: Cust 8538 | P26: 46.69 | Q26: 45435 | R26: 45442 | S26: Ryan | T26: =D26*E26 -> 1440.05 | U26: =T26*H26 -> 0 | V26: =T26-U26 -> 1440.05 | W26: =R26-Q26 -> 7 | X26: =V26-(E26*D26) -> 0 | Y26: =IF(M26 = "Yes", -V26,0) -> 0
A27: 45222 | B27: East | C27: Phone | D27: 13 | E27: 562.29 | F27: Store D | G27: Retail | H27: 0 | I27: Diana | J27: 7309.77 | K27: Gift Card | L27: SAVE10 | M27: 0 | N27: REG100025 | O27: Cust 6322 | P27: 38.13 | Q27: 45222 | R27: 45227 | S27: Eric | T27: =D27*E27 -> 7309.77 | U27: =T27*H27 -> 0 | V27: =T27-U27 -> 7309.77 | W27: =R27-Q27 -> 5 | X27: =V27-(E27*D27) -> 0 | Y27: =IF(M27 = "Yes", -V27,0) -> 0
A28: 45824 | B28: West | C28: Phone | D28: 1 | E28: 101.73 | F28: Store D | G28: Retail | H28: 0 | I28: Frank | J28: 101.73 | K28: Debit Card | L28: WINTER15 | M28: 0 | N28: REG100026 | O28: Cust 2609 | P28: 11.59 | Q28: 45824 | R28: 45833 | S28: Wendy | T28: =D28*E28 -> 101.73 | U28: =T28*H28 -> 0 | V28: =T28-U28 -> 101.73 | W28: =R28-Q28 -> 9 | X28: =V28-(E28*D28) -> 0 | Y28: =IF(M28 = "Yes", -V28,0) -> 0
A29: 44988 | B29: North | C29: Phone | D29: 4 | E29: 279.49 | F29: Store B | G29: Retail | H29: 0 | I29: Diana | J29: 1117.96 | K29: Credit Card | L29: FREESHIP | M29: 0 | N29: REG100027 | O29: Cust 6880 | P29: 24.78 | Q29: 44988 | R29: 44993 | S29: Ryan | T29: =D29*E29 -> 1117.96 | U29: =T29*H29 -> 0 | V29: =T29-U29 -> 1117.96 | W29: =R29-Q29 -> 5 | X29: =V29-(E29*D29) -> 0 | Y29: =IF(M29 = "Yes", -V29,0) -> 0
A30: 45614 | B30: South | C30: Laptop | D30: 1 | E30: 178.55 | F30: Store A | G30: Retail | H30: 0.15 | I30: Carlos | J30: 151.7675 | K30: Debit Card | L30: SAVE10 | M30: 1 | N30: REG100028 | O30: Cust 1997 | P30: 7.61 | Q30: 45614 | R30: 45617 | S30: Sophie | T30: =D30*E30 -> 178.55 | U30: =T30*H30 -> 26.7825 | V30: =T30-U30 -> 151.7675 | W30: =R30-Q30 -> 3 | X30: =V30-(E30*D30) -> -26.7825 | Y30: =IF(M30 = "Yes", -V30,0) -> 0
A31: 45055 | B31: Central | C31: Tablet | D31: 1 | E31: 472.07 | F31: Store A | G31: Wholesale | H31: 0.1 | I31: Carlos | J31: 424.863 | K31: Online | L31: FREESHIP | M31: 0 | N31: REG100029 | O31: Cust 7072 | P31: 33.17 | Q31: 45055 | R31: 45063 | S31: Cameron | T31: =D31*E31 -> 472.07 | U31: =T31*H31 -> 47.207 | V31: =T31-U31 -> 424.863 | W31: =R31-Q31 -> 8 | X31: =V31-(E31*D31) -> -47.207 | Y31: =IF(M31 = "Yes", -V31,0) -> 0
A32: 45633 | B32: North | C32: Tablet | D32: 12 | E32: 306.29 | F32: Store D | G32: Retail | H32: 0 | I32: Frank | J32: 3675.48 | K32: Debit Card | L32: SAVE10 | M32: 0 | N32: REG100030 | O32: Cust 7201 | P32: 37.38 | Q32: 45633 | R32: 45640 | S32: Ryan | T32: =D32*E32 -> 3675.48 | U32: =T32*H32 -> 0 | V32: =T32-U32 -> 3675.48 | W32: =R32-Q32 -> 7 | X32: =V32-(E32*D32) -> 0 | Y32: =IF(M32 = "Yes", -V32,0) -> 0
A33: 45335 | B33: North | C33: Phone | D33: 7 | E33: 434.77 | F33: Store C | G33: Retail | H33: 0.15 | I33: Frank | J33: 2586.8815 | K33: Online | L33: SAVE10 | M33: 0 | N33: REG100031 | O33: Cust 9923 | P33: 12.35 | Q33: 45335 | R33: 45337 | S33: Ryan | T33: =D33*E33 -> 3043.39 | U33: =T33*H33 -> 456.5085 | V33: =T33-U33 -> 2586.8815 | W33: =R33-Q33 -> 2 | X33: =V33-(E33*D33) -> -456.5085 | Y33: =IF(M33 = "Yes", -V33,0) -> 0
A34: 45725 | B34: South | C34: Desk | D34: 6 | E34: 64.98 | F34: Store C | G34: Retail | H34: 0 | I34: Carlos | J34: 389.88 | K34: Debit Card | L34: WINTER15 | M34: 0 | N34: REG100032 | O34: Cust 2205 | P34: 21.25 | Q34: 45725 | R34: 45731 | S34: Sophie | T34: =D34*E34 -> 389.88 | U34: =T34*H34 -> 0 | V34: =T34-U34 -> 389.88 | W34: =R34-Q34 -> 6 | X34: =V34-(E34*D34) -> 0 | Y34: =IF(M34 = "Yes", -V34,0) -> 0
A35: 45021 | B35: Central | C35: Desk | D35: 17 | E35: 476.49 | F35: Store D | G35: Retail | H35: 0 | I35: Alice | J35: 8100.33 | K35: Gift Card | M35: 0 | N35: REG100033 | O35: Cust 6403 | P35: 17.91 | Q35: 45021 | R35: 45027 | S35: Cameron | T35: =D35*E35 -> 8100.33 | U35: =T35*H35 -> 0 | V35: =T35-U35 -> 8100.33 | W35: =R35-Q35 -> 6 | X35: =V35-(E35*D35) -> 0 | Y35: =IF(M35 = "Yes", -V35,0) -> 0
A36: 45785 | B36: North | C36: Monitor | D36: 4 | E36: 559.72 | F36: Store D | G36: Retail | H36: 0.15 | I36: Diana | J36: 1903.048 | K36: Online | L36: SAVE10 | M36: 0 | N36: REG100034 | O36: Cust 3953 | P36: 41.91 | Q36: 45785 | R36: 45789 | S36: Ryan | T36: =D36*E36 -> 2238.88 | U36: =T36*H36 -> 335.832 | V36: =T36-U36 -> 1903.048 | W36: =R36-Q36 -> 4 | X36: =V36-(E36*D36) -> -335.832 | Y36: =IF(M36 = "Yes", -V36,0) -> 0
A37: 45172 | B37: North | C37: Tablet | D37: 14 | E37: 82.14 | F37: Store C | G37: Retail | H37: 0 | I37: Alice | J37: 1149.96 | K37: Credit Card | M37: 0 | N37: REG100035 | O37: Cust 7902 | P37: 12.57 | Q37: 45172 | R37: 45180 | S37: Ryan | T37: =D37*E37 -> 1149.96 | U37: =T37*H37 -> 0 | V37: =T37-U37 -> 1149.96 | W37: =R37-Q37 -> 8 | X37: =V37-(E37*D37) -> 0 | Y37: =IF(M37 = "Yes", -V37,0) -> 0
A38: 45737 | B38: Central | C38: Chair | D38: 9 | E38: 343.21 | F38: Store A | G38: Retail | H38: 0.05 | I38: Carlos | J38: 2934.4455 | K38: Debit Card | L38: FREESHIP | M38: 0 | N38: REG100036 | O38: Cust 9968 | P38: 40.29 | Q38: 45737 | R38: 45744 | S38: Cameron | T38: =D38*E38 -> 3088.89 | U38: =T38*H38 -> 154.4445 | V38: =T38-U38 -> 2934.4455 | W38: =R38-Q38 -> 7 | X38: =V38-(E38*D38) -> -154.4445 | Y38: =IF(M38 = "Yes", -V38,0) -> 0
A39: 45828 | B39: South | C39: Chair | D39: 7 | E39: 301.01 | F39: Store B | G39: Retail | H39: 0.15 | I39: Diana | J39: 1791.0095 | K39: Cash | L39: SAVE10 | M39: 1 | N39: REG100037 | O39: Cust 3787 | P39: 34.97 | Q39: 45828 | R39: 45838 | S39: Sophie | T39: =D39*E39 -> 2107.07 | U39: =T39*H39 -> 316.0605 | V39: =T39-U39 -> 1791.0095 | W39: =R39-Q39 -> 10 | X39: =V39-(E39*D39) -> -316.0605 | Y39: =IF(M39 = "Yes", -V39,0) -> 0
A40: 45337 | B40: Central | C40: Printer | D40: 14 | E40: 428.13 | F40: Store C | G40: Retail | H40: 0.1 | I40: Bob | J40: 5394.438 | K40: Cash | M40: 1 | N40: REG100038 | O40: Cust 2469 | P40: 24.77 | Q40: 45337 | R40: 45347 | S40: Cameron | T40: =D40*E40 -> 5993.82 | U40: =T40*H40 -> 599.382 | V40: =T40-U40 -> 5394.438 | W40: =R40-Q40 -> 10 | X40: =V40-(E40*D40) -> -599.382 | Y40: =IF(M40 = "Yes", -V40,0) -> 0
...
